[2024-12-24T00:00:02.278+0000] {local_task_job_runner.py:123} INFO - ::group::Pre task execution logs
[2024-12-24T00:00:02.322+0000] {taskinstance.py:2612} INFO - Dependencies all met for dep_context=non-requeueable deps ti=<TaskInstance: NY_Pipeline_ETL_and_ML_Training.step_create_original_table scheduled__2024-12-23T00:00:00+00:00 [queued]>
[2024-12-24T00:00:02.352+0000] {taskinstance.py:2612} INFO - Dependencies all met for dep_context=requeueable deps ti=<TaskInstance: NY_Pipeline_ETL_and_ML_Training.step_create_original_table scheduled__2024-12-23T00:00:00+00:00 [queued]>
[2024-12-24T00:00:02.354+0000] {taskinstance.py:2865} INFO - Starting attempt 1 of 2
[2024-12-24T00:00:02.403+0000] {taskinstance.py:2888} INFO - Executing <Task(PythonOperator): step_create_original_table> on 2024-12-23 00:00:00+00:00
[2024-12-24T00:00:02.428+0000] {standard_task_runner.py:104} INFO - Running: ['***', 'tasks', 'run', 'NY_Pipeline_ETL_and_ML_Training', 'step_create_original_table', 'scheduled__2024-12-23T00:00:00+00:00', '--job-id', '25', '--raw', '--subdir', 'DAGS_FOLDER/etl_train_pipeline.py', '--cfg-path', '/tmp/tmpg7pmtry2']
[2024-12-24T00:00:02.438+0000] {standard_task_runner.py:105} INFO - Job 25: Subtask step_create_original_table
[2024-12-24T00:00:02.455+0000] {logging_mixin.py:190} WARNING - /home/***/.local/lib/python3.12/site-packages/***/task/task_runner/standard_task_runner.py:70 DeprecationWarning: This process (pid=201) is multi-threaded, use of fork() may lead to deadlocks in the child.
[2024-12-24T00:00:02.462+0000] {standard_task_runner.py:72} INFO - Started process 203 to run task
[2024-12-24T00:00:02.571+0000] {task_command.py:467} INFO - Running <TaskInstance: NY_Pipeline_ETL_and_ML_Training.step_create_original_table scheduled__2024-12-23T00:00:00+00:00 [running]> on host 8a0d5a4738c0
[2024-12-24T00:00:02.870+0000] {taskinstance.py:3131} INFO - Exporting env vars: AIRFLOW_CTX_DAG_OWNER='Artur Tiburski' AIRFLOW_CTX_DAG_ID='NY_Pipeline_ETL_and_ML_Training' AIRFLOW_CTX_TASK_ID='step_create_original_table' AIRFLOW_CTX_EXECUTION_DATE='2024-12-23T00:00:00+00:00' AIRFLOW_CTX_TRY_NUMBER='1' AIRFLOW_CTX_DAG_RUN_ID='scheduled__2024-12-23T00:00:00+00:00'
[2024-12-24T00:00:02.873+0000] {taskinstance.py:731} INFO - ::endgroup::
[2024-12-24T00:00:03.123+0000] {logging_mixin.py:190} WARNING - /opt/***/***_server/dags/etl_train_pipeline_modules/dsa_carrega_dados.py:60 UserWarning: pandas only supports SQLAlchemy connectable (engine/connection) or database string URI or sqlite3 DBAPI2 connection. Other DBAPI2 objects are not tested. Please consider using SQLAlchemy.
[2024-12-24T00:00:03.126+0000] {logging_mixin.py:190} INFO - An error occurred: BROKERTITLE (VARCHAR(255)) not a string
[2024-12-24T00:00:03.129+0000] {python.py:240} INFO - Done. Returned value was: None
[2024-12-24T00:00:03.152+0000] {taskinstance.py:340} INFO - ::group::Post task execution logs
[2024-12-24T00:00:03.153+0000] {taskinstance.py:352} INFO - Marking task as SUCCESS. dag_id=NY_Pipeline_ETL_and_ML_Training, task_id=step_create_original_table, run_id=scheduled__2024-12-23T00:00:00+00:00, execution_date=20241223T000000, start_date=20241224T000002, end_date=20241224T000003
[2024-12-24T00:00:03.201+0000] {local_task_job_runner.py:266} INFO - Task exited with return code 0
[2024-12-24T00:00:03.215+0000] {local_task_job_runner.py:245} INFO - ::endgroup::
[2024-12-24T00:16:20.722+0000] {local_task_job_runner.py:123} INFO - ::group::Pre task execution logs
[2024-12-24T00:16:20.770+0000] {taskinstance.py:2612} INFO - Dependencies all met for dep_context=non-requeueable deps ti=<TaskInstance: NY_Pipeline_ETL_and_ML_Training.step_create_original_table scheduled__2024-12-23T00:00:00+00:00 [queued]>
[2024-12-24T00:16:20.790+0000] {taskinstance.py:2612} INFO - Dependencies all met for dep_context=requeueable deps ti=<TaskInstance: NY_Pipeline_ETL_and_ML_Training.step_create_original_table scheduled__2024-12-23T00:00:00+00:00 [queued]>
[2024-12-24T00:16:20.791+0000] {taskinstance.py:2865} INFO - Starting attempt 1 of 2
[2024-12-24T00:16:20.833+0000] {taskinstance.py:2888} INFO - Executing <Task(PythonOperator): step_create_original_table> on 2024-12-23 00:00:00+00:00
[2024-12-24T00:16:20.852+0000] {standard_task_runner.py:104} INFO - Running: ['***', 'tasks', 'run', 'NY_Pipeline_ETL_and_ML_Training', 'step_create_original_table', 'scheduled__2024-12-23T00:00:00+00:00', '--job-id', '31', '--raw', '--subdir', 'DAGS_FOLDER/etl_train_pipeline.py', '--cfg-path', '/tmp/tmpat1_397x']
[2024-12-24T00:16:20.863+0000] {standard_task_runner.py:105} INFO - Job 31: Subtask step_create_original_table
[2024-12-24T00:16:20.875+0000] {logging_mixin.py:190} WARNING - /home/***/.local/lib/python3.12/site-packages/***/task/task_runner/standard_task_runner.py:70 DeprecationWarning: This process (pid=645) is multi-threaded, use of fork() may lead to deadlocks in the child.
[2024-12-24T00:16:20.876+0000] {standard_task_runner.py:72} INFO - Started process 651 to run task
[2024-12-24T00:16:20.985+0000] {task_command.py:467} INFO - Running <TaskInstance: NY_Pipeline_ETL_and_ML_Training.step_create_original_table scheduled__2024-12-23T00:00:00+00:00 [running]> on host 8a0d5a4738c0
[2024-12-24T00:16:21.193+0000] {taskinstance.py:3131} INFO - Exporting env vars: AIRFLOW_CTX_DAG_OWNER='Artur Tiburski' AIRFLOW_CTX_DAG_ID='NY_Pipeline_ETL_and_ML_Training' AIRFLOW_CTX_TASK_ID='step_create_original_table' AIRFLOW_CTX_EXECUTION_DATE='2024-12-23T00:00:00+00:00' AIRFLOW_CTX_TRY_NUMBER='1' AIRFLOW_CTX_DAG_RUN_ID='scheduled__2024-12-23T00:00:00+00:00'
[2024-12-24T00:16:21.195+0000] {taskinstance.py:731} INFO - ::endgroup::
[2024-12-24T00:16:23.832+0000] {logging_mixin.py:190} WARNING - /opt/***/***_server/dags/etl_train_pipeline_modules/dsa_carrega_dados.py:55 UserWarning: pandas only supports SQLAlchemy connectable (engine/connection) or database string URI or sqlite3 DBAPI2 connection. Other DBAPI2 objects are not tested. Please consider using SQLAlchemy.
[2024-12-24T00:16:23.834+0000] {logging_mixin.py:190} INFO - An error occurred: BROKERTITLE (VARCHAR(255)) not a string
[2024-12-24T00:16:23.849+0000] {taskinstance.py:3310} ERROR - Task failed with exception
Traceback (most recent call last):
  File "/opt/airflow/airflow_server/dags/etl_train_pipeline_modules/dsa_carrega_dados.py", line 55, in load_csv_to_postgresql
    df.to_sql(
  File "/home/airflow/.local/lib/python3.12/site-packages/pandas/util/_decorators.py", line 333, in wrapper
    return func(*args, **kwargs)
           ^^^^^^^^^^^^^^^^^^^^^
  File "/home/airflow/.local/lib/python3.12/site-packages/pandas/core/generic.py", line 3087, in to_sql
    return sql.to_sql(
           ^^^^^^^^^^^
  File "/home/airflow/.local/lib/python3.12/site-packages/pandas/io/sql.py", line 842, in to_sql
    return pandas_sql.to_sql(
           ^^^^^^^^^^^^^^^^^^
  File "/home/airflow/.local/lib/python3.12/site-packages/pandas/io/sql.py", line 2839, in to_sql
    raise ValueError(f"{col} ({my_type}) not a string")
ValueError: BROKERTITLE (VARCHAR(255)) not a string

During handling of the above exception, another exception occurred:

Traceback (most recent call last):
  File "/home/airflow/.local/lib/python3.12/site-packages/airflow/models/taskinstance.py", line 767, in _execute_task
    result = _execute_callable(context=context, **execute_callable_kwargs)
             ^^^^^^^^^^^^^^^^^^^^^^^^^^^^^^^^^^^^^^^^^^^^^^^^^^^^^^^^^^^^^
  File "/home/airflow/.local/lib/python3.12/site-packages/airflow/models/taskinstance.py", line 733, in _execute_callable
    return ExecutionCallableRunner(
           ^^^^^^^^^^^^^^^^^^^^^^^^
  File "/home/airflow/.local/lib/python3.12/site-packages/airflow/utils/operator_helpers.py", line 252, in run
    return self.func(*args, **kwargs)
           ^^^^^^^^^^^^^^^^^^^^^^^^^^
  File "/home/airflow/.local/lib/python3.12/site-packages/airflow/models/baseoperator.py", line 406, in wrapper
    return func(self, *args, **kwargs)
           ^^^^^^^^^^^^^^^^^^^^^^^^^^^
  File "/home/airflow/.local/lib/python3.12/site-packages/airflow/operators/python.py", line 238, in execute
    return_value = self.execute_callable()
                   ^^^^^^^^^^^^^^^^^^^^^^^
  File "/home/airflow/.local/lib/python3.12/site-packages/airflow/operators/python.py", line 256, in execute_callable
    return runner.run(*self.op_args, **self.op_kwargs)
           ^^^^^^^^^^^^^^^^^^^^^^^^^^^^^^^^^^^^^^^^^^^
  File "/home/airflow/.local/lib/python3.12/site-packages/airflow/utils/operator_helpers.py", line 252, in run
    return self.func(*args, **kwargs)
           ^^^^^^^^^^^^^^^^^^^^^^^^^^
  File "/opt/airflow/airflow_server/dags/etl_train_pipeline_modules/dsa_carrega_dados.py", line 69, in load_csv_to_postgresql
    raise AirflowException(f"Task failed due to error: {str(e)}")
airflow.exceptions.AirflowException: Task failed due to error: BROKERTITLE (VARCHAR(255)) not a string
[2024-12-24T00:16:23.876+0000] {taskinstance.py:1225} INFO - Marking task as UP_FOR_RETRY. dag_id=NY_Pipeline_ETL_and_ML_Training, task_id=step_create_original_table, run_id=scheduled__2024-12-23T00:00:00+00:00, execution_date=20241223T000000, start_date=20241224T001620, end_date=20241224T001623
[2024-12-24T00:16:23.921+0000] {taskinstance.py:340} INFO - ::group::Post task execution logs
[2024-12-24T00:16:23.922+0000] {standard_task_runner.py:124} ERROR - Failed to execute job 31 for task step_create_original_table (Task failed due to error: BROKERTITLE (VARCHAR(255)) not a string; 651)
Traceback (most recent call last):
  File "/opt/airflow/airflow_server/dags/etl_train_pipeline_modules/dsa_carrega_dados.py", line 55, in load_csv_to_postgresql
    df.to_sql(
  File "/home/airflow/.local/lib/python3.12/site-packages/pandas/util/_decorators.py", line 333, in wrapper
    return func(*args, **kwargs)
           ^^^^^^^^^^^^^^^^^^^^^
  File "/home/airflow/.local/lib/python3.12/site-packages/pandas/core/generic.py", line 3087, in to_sql
    return sql.to_sql(
           ^^^^^^^^^^^
  File "/home/airflow/.local/lib/python3.12/site-packages/pandas/io/sql.py", line 842, in to_sql
    return pandas_sql.to_sql(
           ^^^^^^^^^^^^^^^^^^
  File "/home/airflow/.local/lib/python3.12/site-packages/pandas/io/sql.py", line 2839, in to_sql
    raise ValueError(f"{col} ({my_type}) not a string")
ValueError: BROKERTITLE (VARCHAR(255)) not a string

During handling of the above exception, another exception occurred:

Traceback (most recent call last):
  File "/home/airflow/.local/lib/python3.12/site-packages/airflow/task/task_runner/standard_task_runner.py", line 117, in _start_by_fork
    ret = args.func(args, dag=self.dag)
          ^^^^^^^^^^^^^^^^^^^^^^^^^^^^^
  File "/home/airflow/.local/lib/python3.12/site-packages/airflow/cli/cli_config.py", line 49, in command
    return func(*args, **kwargs)
           ^^^^^^^^^^^^^^^^^^^^^
  File "/home/airflow/.local/lib/python3.12/site-packages/airflow/utils/cli.py", line 115, in wrapper
    return f(*args, **kwargs)
           ^^^^^^^^^^^^^^^^^^
  File "/home/airflow/.local/lib/python3.12/site-packages/airflow/cli/commands/task_command.py", line 483, in task_run
    task_return_code = _run_task_by_selected_method(args, _dag, ti)
                       ^^^^^^^^^^^^^^^^^^^^^^^^^^^^^^^^^^^^^^^^^^^^
  File "/home/airflow/.local/lib/python3.12/site-packages/airflow/cli/commands/task_command.py", line 256, in _run_task_by_selected_method
    return _run_raw_task(args, ti)
           ^^^^^^^^^^^^^^^^^^^^^^^
  File "/home/airflow/.local/lib/python3.12/site-packages/airflow/cli/commands/task_command.py", line 341, in _run_raw_task
    return ti._run_raw_task(
           ^^^^^^^^^^^^^^^^^
  File "/home/airflow/.local/lib/python3.12/site-packages/airflow/utils/session.py", line 97, in wrapper
    return func(*args, session=session, **kwargs)
           ^^^^^^^^^^^^^^^^^^^^^^^^^^^^^^^^^^^^^^
  File "/home/airflow/.local/lib/python3.12/site-packages/airflow/models/taskinstance.py", line 3004, in _run_raw_task
    return _run_raw_task(
           ^^^^^^^^^^^^^^
  File "/home/airflow/.local/lib/python3.12/site-packages/airflow/models/taskinstance.py", line 273, in _run_raw_task
    TaskInstance._execute_task_with_callbacks(
  File "/home/airflow/.local/lib/python3.12/site-packages/airflow/models/taskinstance.py", line 3158, in _execute_task_with_callbacks
    result = self._execute_task(context, task_orig)
             ^^^^^^^^^^^^^^^^^^^^^^^^^^^^^^^^^^^^^^
  File "/home/airflow/.local/lib/python3.12/site-packages/airflow/models/taskinstance.py", line 3182, in _execute_task
    return _execute_task(self, context, task_orig)
           ^^^^^^^^^^^^^^^^^^^^^^^^^^^^^^^^^^^^^^^
  File "/home/airflow/.local/lib/python3.12/site-packages/airflow/models/taskinstance.py", line 767, in _execute_task
    result = _execute_callable(context=context, **execute_callable_kwargs)
             ^^^^^^^^^^^^^^^^^^^^^^^^^^^^^^^^^^^^^^^^^^^^^^^^^^^^^^^^^^^^^
  File "/home/airflow/.local/lib/python3.12/site-packages/airflow/models/taskinstance.py", line 733, in _execute_callable
    return ExecutionCallableRunner(
           ^^^^^^^^^^^^^^^^^^^^^^^^
  File "/home/airflow/.local/lib/python3.12/site-packages/airflow/utils/operator_helpers.py", line 252, in run
    return self.func(*args, **kwargs)
           ^^^^^^^^^^^^^^^^^^^^^^^^^^
  File "/home/airflow/.local/lib/python3.12/site-packages/airflow/models/baseoperator.py", line 406, in wrapper
    return func(self, *args, **kwargs)
           ^^^^^^^^^^^^^^^^^^^^^^^^^^^
  File "/home/airflow/.local/lib/python3.12/site-packages/airflow/operators/python.py", line 238, in execute
    return_value = self.execute_callable()
                   ^^^^^^^^^^^^^^^^^^^^^^^
  File "/home/airflow/.local/lib/python3.12/site-packages/airflow/operators/python.py", line 256, in execute_callable
    return runner.run(*self.op_args, **self.op_kwargs)
           ^^^^^^^^^^^^^^^^^^^^^^^^^^^^^^^^^^^^^^^^^^^
  File "/home/airflow/.local/lib/python3.12/site-packages/airflow/utils/operator_helpers.py", line 252, in run
    return self.func(*args, **kwargs)
           ^^^^^^^^^^^^^^^^^^^^^^^^^^
  File "/opt/airflow/airflow_server/dags/etl_train_pipeline_modules/dsa_carrega_dados.py", line 69, in load_csv_to_postgresql
    raise AirflowException(f"Task failed due to error: {str(e)}")
airflow.exceptions.AirflowException: Task failed due to error: BROKERTITLE (VARCHAR(255)) not a string
[2024-12-24T00:16:23.970+0000] {local_task_job_runner.py:266} INFO - Task exited with return code 1
[2024-12-24T00:16:24.002+0000] {taskinstance.py:3900} INFO - 0 downstream tasks scheduled from follow-on schedule check
[2024-12-24T00:16:24.010+0000] {local_task_job_runner.py:245} INFO - ::endgroup::
[2024-12-24T00:22:41.360+0000] {local_task_job_runner.py:123} INFO - ::group::Pre task execution logs
[2024-12-24T00:22:41.412+0000] {taskinstance.py:2612} INFO - Dependencies all met for dep_context=non-requeueable deps ti=<TaskInstance: NY_Pipeline_ETL_and_ML_Training.step_create_original_table scheduled__2024-12-23T00:00:00+00:00 [queued]>
[2024-12-24T00:22:41.460+0000] {taskinstance.py:2612} INFO - Dependencies all met for dep_context=requeueable deps ti=<TaskInstance: NY_Pipeline_ETL_and_ML_Training.step_create_original_table scheduled__2024-12-23T00:00:00+00:00 [queued]>
[2024-12-24T00:22:41.463+0000] {taskinstance.py:2865} INFO - Starting attempt 1 of 2
[2024-12-24T00:22:41.494+0000] {taskinstance.py:2888} INFO - Executing <Task(PythonOperator): step_create_original_table> on 2024-12-23 00:00:00+00:00
[2024-12-24T00:22:41.510+0000] {standard_task_runner.py:104} INFO - Running: ['***', 'tasks', 'run', 'NY_Pipeline_ETL_and_ML_Training', 'step_create_original_table', 'scheduled__2024-12-23T00:00:00+00:00', '--job-id', '33', '--raw', '--subdir', 'DAGS_FOLDER/etl_train_pipeline.py', '--cfg-path', '/tmp/tmpxw4x9v4k']
[2024-12-24T00:22:41.516+0000] {standard_task_runner.py:105} INFO - Job 33: Subtask step_create_original_table
[2024-12-24T00:22:41.523+0000] {logging_mixin.py:190} WARNING - /home/***/.local/lib/python3.12/site-packages/***/task/task_runner/standard_task_runner.py:70 DeprecationWarning: This process (pid=803) is multi-threaded, use of fork() may lead to deadlocks in the child.
[2024-12-24T00:22:41.524+0000] {standard_task_runner.py:72} INFO - Started process 805 to run task
[2024-12-24T00:22:41.609+0000] {task_command.py:467} INFO - Running <TaskInstance: NY_Pipeline_ETL_and_ML_Training.step_create_original_table scheduled__2024-12-23T00:00:00+00:00 [running]> on host 8a0d5a4738c0
[2024-12-24T00:22:41.789+0000] {taskinstance.py:3131} INFO - Exporting env vars: AIRFLOW_CTX_DAG_OWNER='Artur Tiburski' AIRFLOW_CTX_DAG_ID='NY_Pipeline_ETL_and_ML_Training' AIRFLOW_CTX_TASK_ID='step_create_original_table' AIRFLOW_CTX_EXECUTION_DATE='2024-12-23T00:00:00+00:00' AIRFLOW_CTX_TRY_NUMBER='1' AIRFLOW_CTX_DAG_RUN_ID='scheduled__2024-12-23T00:00:00+00:00'
[2024-12-24T00:22:41.793+0000] {taskinstance.py:731} INFO - ::endgroup::
[2024-12-24T00:22:44.478+0000] {logging_mixin.py:190} WARNING - /opt/***/***_server/dags/etl_train_pipeline_modules/dsa_carrega_dados.py:55 UserWarning: pandas only supports SQLAlchemy connectable (engine/connection) or database string URI or sqlite3 DBAPI2 connection. Other DBAPI2 objects are not tested. Please consider using SQLAlchemy.
[2024-12-24T00:22:44.498+0000] {taskinstance.py:3310} ERROR - Task failed with exception
Traceback (most recent call last):
  File "/opt/airflow/airflow_server/dags/etl_train_pipeline_modules/dsa_carrega_dados.py", line 55, in load_csv_to_postgresql
    df.to_sql(
  File "/home/airflow/.local/lib/python3.12/site-packages/pandas/util/_decorators.py", line 333, in wrapper
    return func(*args, **kwargs)
           ^^^^^^^^^^^^^^^^^^^^^
  File "/home/airflow/.local/lib/python3.12/site-packages/pandas/core/generic.py", line 3087, in to_sql
    return sql.to_sql(
           ^^^^^^^^^^^
  File "/home/airflow/.local/lib/python3.12/site-packages/pandas/io/sql.py", line 842, in to_sql
    return pandas_sql.to_sql(
           ^^^^^^^^^^^^^^^^^^
  File "/home/airflow/.local/lib/python3.12/site-packages/pandas/io/sql.py", line 2839, in to_sql
    raise ValueError(f"{col} ({my_type}) not a string")
ValueError: BROKERTITLE (VARCHAR(255)) not a string

During handling of the above exception, another exception occurred:

Traceback (most recent call last):
  File "/home/airflow/.local/lib/python3.12/site-packages/airflow/models/taskinstance.py", line 767, in _execute_task
    result = _execute_callable(context=context, **execute_callable_kwargs)
             ^^^^^^^^^^^^^^^^^^^^^^^^^^^^^^^^^^^^^^^^^^^^^^^^^^^^^^^^^^^^^
  File "/home/airflow/.local/lib/python3.12/site-packages/airflow/models/taskinstance.py", line 733, in _execute_callable
    return ExecutionCallableRunner(
           ^^^^^^^^^^^^^^^^^^^^^^^^
  File "/home/airflow/.local/lib/python3.12/site-packages/airflow/utils/operator_helpers.py", line 252, in run
    return self.func(*args, **kwargs)
           ^^^^^^^^^^^^^^^^^^^^^^^^^^
  File "/home/airflow/.local/lib/python3.12/site-packages/airflow/models/baseoperator.py", line 406, in wrapper
    return func(self, *args, **kwargs)
           ^^^^^^^^^^^^^^^^^^^^^^^^^^^
  File "/home/airflow/.local/lib/python3.12/site-packages/airflow/operators/python.py", line 238, in execute
    return_value = self.execute_callable()
                   ^^^^^^^^^^^^^^^^^^^^^^^
  File "/home/airflow/.local/lib/python3.12/site-packages/airflow/operators/python.py", line 256, in execute_callable
    return runner.run(*self.op_args, **self.op_kwargs)
           ^^^^^^^^^^^^^^^^^^^^^^^^^^^^^^^^^^^^^^^^^^^
  File "/home/airflow/.local/lib/python3.12/site-packages/airflow/utils/operator_helpers.py", line 252, in run
    return self.func(*args, **kwargs)
           ^^^^^^^^^^^^^^^^^^^^^^^^^^
  File "/opt/airflow/airflow_server/dags/etl_train_pipeline_modules/dsa_carrega_dados.py", line 68, in load_csv_to_postgresql
    raise AirflowException(f"Task failed due to error: {str(e)}")
airflow.exceptions.AirflowException: Task failed due to error: BROKERTITLE (VARCHAR(255)) not a string
[2024-12-24T00:22:44.522+0000] {taskinstance.py:1225} INFO - Marking task as UP_FOR_RETRY. dag_id=NY_Pipeline_ETL_and_ML_Training, task_id=step_create_original_table, run_id=scheduled__2024-12-23T00:00:00+00:00, execution_date=20241223T000000, start_date=20241224T002241, end_date=20241224T002244
[2024-12-24T00:22:44.554+0000] {taskinstance.py:340} INFO - ::group::Post task execution logs
[2024-12-24T00:22:44.559+0000] {standard_task_runner.py:124} ERROR - Failed to execute job 33 for task step_create_original_table (Task failed due to error: BROKERTITLE (VARCHAR(255)) not a string; 805)
Traceback (most recent call last):
  File "/opt/airflow/airflow_server/dags/etl_train_pipeline_modules/dsa_carrega_dados.py", line 55, in load_csv_to_postgresql
    df.to_sql(
  File "/home/airflow/.local/lib/python3.12/site-packages/pandas/util/_decorators.py", line 333, in wrapper
    return func(*args, **kwargs)
           ^^^^^^^^^^^^^^^^^^^^^
  File "/home/airflow/.local/lib/python3.12/site-packages/pandas/core/generic.py", line 3087, in to_sql
    return sql.to_sql(
           ^^^^^^^^^^^
  File "/home/airflow/.local/lib/python3.12/site-packages/pandas/io/sql.py", line 842, in to_sql
    return pandas_sql.to_sql(
           ^^^^^^^^^^^^^^^^^^
  File "/home/airflow/.local/lib/python3.12/site-packages/pandas/io/sql.py", line 2839, in to_sql
    raise ValueError(f"{col} ({my_type}) not a string")
ValueError: BROKERTITLE (VARCHAR(255)) not a string

During handling of the above exception, another exception occurred:

Traceback (most recent call last):
  File "/home/airflow/.local/lib/python3.12/site-packages/airflow/task/task_runner/standard_task_runner.py", line 117, in _start_by_fork
    ret = args.func(args, dag=self.dag)
          ^^^^^^^^^^^^^^^^^^^^^^^^^^^^^
  File "/home/airflow/.local/lib/python3.12/site-packages/airflow/cli/cli_config.py", line 49, in command
    return func(*args, **kwargs)
           ^^^^^^^^^^^^^^^^^^^^^
  File "/home/airflow/.local/lib/python3.12/site-packages/airflow/utils/cli.py", line 115, in wrapper
    return f(*args, **kwargs)
           ^^^^^^^^^^^^^^^^^^
  File "/home/airflow/.local/lib/python3.12/site-packages/airflow/cli/commands/task_command.py", line 483, in task_run
    task_return_code = _run_task_by_selected_method(args, _dag, ti)
                       ^^^^^^^^^^^^^^^^^^^^^^^^^^^^^^^^^^^^^^^^^^^^
  File "/home/airflow/.local/lib/python3.12/site-packages/airflow/cli/commands/task_command.py", line 256, in _run_task_by_selected_method
    return _run_raw_task(args, ti)
           ^^^^^^^^^^^^^^^^^^^^^^^
  File "/home/airflow/.local/lib/python3.12/site-packages/airflow/cli/commands/task_command.py", line 341, in _run_raw_task
    return ti._run_raw_task(
           ^^^^^^^^^^^^^^^^^
  File "/home/airflow/.local/lib/python3.12/site-packages/airflow/utils/session.py", line 97, in wrapper
    return func(*args, session=session, **kwargs)
           ^^^^^^^^^^^^^^^^^^^^^^^^^^^^^^^^^^^^^^
  File "/home/airflow/.local/lib/python3.12/site-packages/airflow/models/taskinstance.py", line 3004, in _run_raw_task
    return _run_raw_task(
           ^^^^^^^^^^^^^^
  File "/home/airflow/.local/lib/python3.12/site-packages/airflow/models/taskinstance.py", line 273, in _run_raw_task
    TaskInstance._execute_task_with_callbacks(
  File "/home/airflow/.local/lib/python3.12/site-packages/airflow/models/taskinstance.py", line 3158, in _execute_task_with_callbacks
    result = self._execute_task(context, task_orig)
             ^^^^^^^^^^^^^^^^^^^^^^^^^^^^^^^^^^^^^^
  File "/home/airflow/.local/lib/python3.12/site-packages/airflow/models/taskinstance.py", line 3182, in _execute_task
    return _execute_task(self, context, task_orig)
           ^^^^^^^^^^^^^^^^^^^^^^^^^^^^^^^^^^^^^^^
  File "/home/airflow/.local/lib/python3.12/site-packages/airflow/models/taskinstance.py", line 767, in _execute_task
    result = _execute_callable(context=context, **execute_callable_kwargs)
             ^^^^^^^^^^^^^^^^^^^^^^^^^^^^^^^^^^^^^^^^^^^^^^^^^^^^^^^^^^^^^
  File "/home/airflow/.local/lib/python3.12/site-packages/airflow/models/taskinstance.py", line 733, in _execute_callable
    return ExecutionCallableRunner(
           ^^^^^^^^^^^^^^^^^^^^^^^^
  File "/home/airflow/.local/lib/python3.12/site-packages/airflow/utils/operator_helpers.py", line 252, in run
    return self.func(*args, **kwargs)
           ^^^^^^^^^^^^^^^^^^^^^^^^^^
  File "/home/airflow/.local/lib/python3.12/site-packages/airflow/models/baseoperator.py", line 406, in wrapper
    return func(self, *args, **kwargs)
           ^^^^^^^^^^^^^^^^^^^^^^^^^^^
  File "/home/airflow/.local/lib/python3.12/site-packages/airflow/operators/python.py", line 238, in execute
    return_value = self.execute_callable()
                   ^^^^^^^^^^^^^^^^^^^^^^^
  File "/home/airflow/.local/lib/python3.12/site-packages/airflow/operators/python.py", line 256, in execute_callable
    return runner.run(*self.op_args, **self.op_kwargs)
           ^^^^^^^^^^^^^^^^^^^^^^^^^^^^^^^^^^^^^^^^^^^
  File "/home/airflow/.local/lib/python3.12/site-packages/airflow/utils/operator_helpers.py", line 252, in run
    return self.func(*args, **kwargs)
           ^^^^^^^^^^^^^^^^^^^^^^^^^^
  File "/opt/airflow/airflow_server/dags/etl_train_pipeline_modules/dsa_carrega_dados.py", line 68, in load_csv_to_postgresql
    raise AirflowException(f"Task failed due to error: {str(e)}")
airflow.exceptions.AirflowException: Task failed due to error: BROKERTITLE (VARCHAR(255)) not a string
[2024-12-24T00:22:44.610+0000] {local_task_job_runner.py:266} INFO - Task exited with return code 1
[2024-12-24T00:22:44.649+0000] {taskinstance.py:3900} INFO - 0 downstream tasks scheduled from follow-on schedule check
[2024-12-24T00:22:44.665+0000] {local_task_job_runner.py:245} INFO - ::endgroup::
[2024-12-24T00:52:48.684+0000] {local_task_job_runner.py:123} INFO - ::group::Pre task execution logs
[2024-12-24T00:52:48.749+0000] {taskinstance.py:2612} INFO - Dependencies all met for dep_context=non-requeueable deps ti=<TaskInstance: NY_Pipeline_ETL_and_ML_Training.step_create_original_table scheduled__2024-12-23T00:00:00+00:00 [queued]>
[2024-12-24T00:52:48.774+0000] {taskinstance.py:2612} INFO - Dependencies all met for dep_context=requeueable deps ti=<TaskInstance: NY_Pipeline_ETL_and_ML_Training.step_create_original_table scheduled__2024-12-23T00:00:00+00:00 [queued]>
[2024-12-24T00:52:48.777+0000] {taskinstance.py:2865} INFO - Starting attempt 1 of 2
[2024-12-24T00:52:48.812+0000] {taskinstance.py:2888} INFO - Executing <Task(PythonOperator): step_create_original_table> on 2024-12-23 00:00:00+00:00
[2024-12-24T00:52:48.856+0000] {standard_task_runner.py:104} INFO - Running: ['***', 'tasks', 'run', 'NY_Pipeline_ETL_and_ML_Training', 'step_create_original_table', 'scheduled__2024-12-23T00:00:00+00:00', '--job-id', '3', '--raw', '--subdir', 'DAGS_FOLDER/etl_train_pipeline.py', '--cfg-path', '/tmp/tmpbhdqu2r0']
[2024-12-24T00:52:48.876+0000] {standard_task_runner.py:105} INFO - Job 3: Subtask step_create_original_table
[2024-12-24T00:52:48.902+0000] {logging_mixin.py:190} WARNING - /home/***/.local/lib/python3.12/site-packages/***/task/task_runner/standard_task_runner.py:70 DeprecationWarning: This process (pid=188) is multi-threaded, use of fork() may lead to deadlocks in the child.
[2024-12-24T00:52:48.906+0000] {standard_task_runner.py:72} INFO - Started process 193 to run task
[2024-12-24T00:52:49.196+0000] {task_command.py:467} INFO - Running <TaskInstance: NY_Pipeline_ETL_and_ML_Training.step_create_original_table scheduled__2024-12-23T00:00:00+00:00 [running]> on host 9c7b8f26d27a
[2024-12-24T00:52:49.610+0000] {taskinstance.py:3131} INFO - Exporting env vars: AIRFLOW_CTX_DAG_OWNER='Artur Tiburski' AIRFLOW_CTX_DAG_ID='NY_Pipeline_ETL_and_ML_Training' AIRFLOW_CTX_TASK_ID='step_create_original_table' AIRFLOW_CTX_EXECUTION_DATE='2024-12-23T00:00:00+00:00' AIRFLOW_CTX_TRY_NUMBER='1' AIRFLOW_CTX_DAG_RUN_ID='scheduled__2024-12-23T00:00:00+00:00'
[2024-12-24T00:52:49.616+0000] {taskinstance.py:731} INFO - ::endgroup::
[2024-12-24T00:55:05.297+0000] {local_task_job_runner.py:346} WARNING - State of this instance has been externally set to None. Terminating instance.
[2024-12-24T00:55:05.300+0000] {local_task_job_runner.py:245} INFO - ::endgroup::
[2024-12-24T00:55:05.302+0000] {process_utils.py:132} INFO - Sending 15 to group 193. PIDs of all processes in the group: [193]
[2024-12-24T00:55:05.304+0000] {process_utils.py:87} INFO - Sending the signal 15 to group 193
[2024-12-24T00:55:05.428+0000] {taskinstance.py:3092} ERROR - Received SIGTERM. Terminating subprocesses.
[2024-12-24T00:55:05.432+0000] {logging_mixin.py:190} INFO - Database connection closed.
[2024-12-24T00:55:05.446+0000] {taskinstance.py:3310} ERROR - Task failed with exception
Traceback (most recent call last):
  File "/home/airflow/.local/lib/python3.12/site-packages/airflow/models/taskinstance.py", line 767, in _execute_task
    result = _execute_callable(context=context, **execute_callable_kwargs)
             ^^^^^^^^^^^^^^^^^^^^^^^^^^^^^^^^^^^^^^^^^^^^^^^^^^^^^^^^^^^^^
  File "/home/airflow/.local/lib/python3.12/site-packages/airflow/models/taskinstance.py", line 733, in _execute_callable
    return ExecutionCallableRunner(
           ^^^^^^^^^^^^^^^^^^^^^^^^
  File "/home/airflow/.local/lib/python3.12/site-packages/airflow/utils/operator_helpers.py", line 252, in run
    return self.func(*args, **kwargs)
           ^^^^^^^^^^^^^^^^^^^^^^^^^^
  File "/home/airflow/.local/lib/python3.12/site-packages/airflow/models/baseoperator.py", line 406, in wrapper
    return func(self, *args, **kwargs)
           ^^^^^^^^^^^^^^^^^^^^^^^^^^^
  File "/home/airflow/.local/lib/python3.12/site-packages/airflow/operators/python.py", line 238, in execute
    return_value = self.execute_callable()
                   ^^^^^^^^^^^^^^^^^^^^^^^
  File "/home/airflow/.local/lib/python3.12/site-packages/airflow/operators/python.py", line 256, in execute_callable
    return runner.run(*self.op_args, **self.op_kwargs)
           ^^^^^^^^^^^^^^^^^^^^^^^^^^^^^^^^^^^^^^^^^^^
  File "/home/airflow/.local/lib/python3.12/site-packages/airflow/utils/operator_helpers.py", line 252, in run
    return self.func(*args, **kwargs)
           ^^^^^^^^^^^^^^^^^^^^^^^^^^
  File "/opt/airflow/airflow_server/dags/etl_train_pipeline_modules/dsa_carrega_dados.py", line 71, in load_csv_to_postgresql
    connection.execute(insert_query, chunk)
  File "/home/airflow/.local/lib/python3.12/site-packages/sqlalchemy/engine/base.py", line 1385, in execute
    return meth(self, multiparams, params, _EMPTY_EXECUTION_OPTS)
           ^^^^^^^^^^^^^^^^^^^^^^^^^^^^^^^^^^^^^^^^^^^^^^^^^^^^^^
  File "/home/airflow/.local/lib/python3.12/site-packages/sqlalchemy/sql/elements.py", line 334, in _execute_on_connection
    return connection._execute_clauseelement(
           ^^^^^^^^^^^^^^^^^^^^^^^^^^^^^^^^^^
  File "/home/airflow/.local/lib/python3.12/site-packages/sqlalchemy/engine/base.py", line 1577, in _execute_clauseelement
    ret = self._execute_context(
          ^^^^^^^^^^^^^^^^^^^^^^
  File "/home/airflow/.local/lib/python3.12/site-packages/sqlalchemy/engine/base.py", line 1953, in _execute_context
    self._handle_dbapi_exception(
  File "/home/airflow/.local/lib/python3.12/site-packages/sqlalchemy/engine/base.py", line 2138, in _handle_dbapi_exception
    util.raise_(exc_info[1], with_traceback=exc_info[2])
  File "/home/airflow/.local/lib/python3.12/site-packages/sqlalchemy/util/compat.py", line 211, in raise_
    raise exception
  File "/home/airflow/.local/lib/python3.12/site-packages/sqlalchemy/engine/base.py", line 1890, in _execute_context
    self.dialect.do_executemany(
  File "/home/airflow/.local/lib/python3.12/site-packages/sqlalchemy/dialects/postgresql/psycopg2.py", line 1000, in do_executemany
    cursor.executemany(statement, parameters)
  File "/usr/local/lib/python3.12/encodings/utf_8.py", line 15, in decode
    def decode(input, errors='strict'):
    
  File "/home/airflow/.local/lib/python3.12/site-packages/airflow/models/taskinstance.py", line 3094, in signal_handler
    raise AirflowTaskTerminated("Task received SIGTERM signal")
airflow.exceptions.AirflowTaskTerminated: Task received SIGTERM signal
[2024-12-24T00:55:05.469+0000] {taskinstance.py:1225} INFO - Marking task as UP_FOR_RETRY. dag_id=NY_Pipeline_ETL_and_ML_Training, task_id=step_create_original_table, run_id=scheduled__2024-12-23T00:00:00+00:00, execution_date=20241223T000000, start_date=20241224T005248, end_date=20241224T005505
[2024-12-24T00:55:05.494+0000] {taskinstance.py:340} INFO - ::group::Post task execution logs
[2024-12-24T00:55:05.495+0000] {standard_task_runner.py:124} ERROR - Failed to execute job 3 for task step_create_original_table ((psycopg2.errors.ForeignKeyViolation) insert or update on table "task_fail" violates foreign key constraint "task_fail_ti_fkey"
DETAIL:  Key (dag_id, task_id, run_id, map_index)=(NY_Pipeline_ETL_and_ML_Training, step_create_original_table, scheduled__2024-12-23T00:00:00+00:00, -1) is not present in table "task_instance".

[SQL: INSERT INTO task_fail (task_id, dag_id, run_id, map_index, start_date, end_date, duration) VALUES (%(task_id)s, %(dag_id)s, %(run_id)s, %(map_index)s, %(start_date)s, %(end_date)s, %(duration)s) RETURNING task_fail.id]
[parameters: {'task_id': 'step_create_original_table', 'dag_id': 'NY_Pipeline_ETL_and_ML_Training', 'run_id': 'scheduled__2024-12-23T00:00:00+00:00', 'map_index': -1, 'start_date': datetime.datetime(2024, 12, 24, 0, 52, 48, 751862, tzinfo=Timezone('UTC')), 'end_date': datetime.datetime(2024, 12, 24, 0, 55, 5, 468504, tzinfo=Timezone('UTC')), 'duration': 136}]
(Background on this error at: https://sqlalche.me/e/14/gkpj); 193)
Traceback (most recent call last):
  File "/home/airflow/.local/lib/python3.12/site-packages/airflow/models/taskinstance.py", line 273, in _run_raw_task
    TaskInstance._execute_task_with_callbacks(
  File "/home/airflow/.local/lib/python3.12/site-packages/airflow/models/taskinstance.py", line 3158, in _execute_task_with_callbacks
    result = self._execute_task(context, task_orig)
             ^^^^^^^^^^^^^^^^^^^^^^^^^^^^^^^^^^^^^^
  File "/home/airflow/.local/lib/python3.12/site-packages/airflow/models/taskinstance.py", line 3182, in _execute_task
    return _execute_task(self, context, task_orig)
           ^^^^^^^^^^^^^^^^^^^^^^^^^^^^^^^^^^^^^^^
  File "/home/airflow/.local/lib/python3.12/site-packages/airflow/models/taskinstance.py", line 767, in _execute_task
    result = _execute_callable(context=context, **execute_callable_kwargs)
             ^^^^^^^^^^^^^^^^^^^^^^^^^^^^^^^^^^^^^^^^^^^^^^^^^^^^^^^^^^^^^
  File "/home/airflow/.local/lib/python3.12/site-packages/airflow/models/taskinstance.py", line 733, in _execute_callable
    return ExecutionCallableRunner(
           ^^^^^^^^^^^^^^^^^^^^^^^^
  File "/home/airflow/.local/lib/python3.12/site-packages/airflow/utils/operator_helpers.py", line 252, in run
    return self.func(*args, **kwargs)
           ^^^^^^^^^^^^^^^^^^^^^^^^^^
  File "/home/airflow/.local/lib/python3.12/site-packages/airflow/models/baseoperator.py", line 406, in wrapper
    return func(self, *args, **kwargs)
           ^^^^^^^^^^^^^^^^^^^^^^^^^^^
  File "/home/airflow/.local/lib/python3.12/site-packages/airflow/operators/python.py", line 238, in execute
    return_value = self.execute_callable()
                   ^^^^^^^^^^^^^^^^^^^^^^^
  File "/home/airflow/.local/lib/python3.12/site-packages/airflow/operators/python.py", line 256, in execute_callable
    return runner.run(*self.op_args, **self.op_kwargs)
           ^^^^^^^^^^^^^^^^^^^^^^^^^^^^^^^^^^^^^^^^^^^
  File "/home/airflow/.local/lib/python3.12/site-packages/airflow/utils/operator_helpers.py", line 252, in run
    return self.func(*args, **kwargs)
           ^^^^^^^^^^^^^^^^^^^^^^^^^^
  File "/opt/airflow/airflow_server/dags/etl_train_pipeline_modules/dsa_carrega_dados.py", line 71, in load_csv_to_postgresql
    connection.execute(insert_query, chunk)
  File "/home/airflow/.local/lib/python3.12/site-packages/sqlalchemy/engine/base.py", line 1385, in execute
    return meth(self, multiparams, params, _EMPTY_EXECUTION_OPTS)
           ^^^^^^^^^^^^^^^^^^^^^^^^^^^^^^^^^^^^^^^^^^^^^^^^^^^^^^
  File "/home/airflow/.local/lib/python3.12/site-packages/sqlalchemy/sql/elements.py", line 334, in _execute_on_connection
    return connection._execute_clauseelement(
           ^^^^^^^^^^^^^^^^^^^^^^^^^^^^^^^^^^
  File "/home/airflow/.local/lib/python3.12/site-packages/sqlalchemy/engine/base.py", line 1577, in _execute_clauseelement
    ret = self._execute_context(
          ^^^^^^^^^^^^^^^^^^^^^^
  File "/home/airflow/.local/lib/python3.12/site-packages/sqlalchemy/engine/base.py", line 1953, in _execute_context
    self._handle_dbapi_exception(
  File "/home/airflow/.local/lib/python3.12/site-packages/sqlalchemy/engine/base.py", line 2138, in _handle_dbapi_exception
    util.raise_(exc_info[1], with_traceback=exc_info[2])
  File "/home/airflow/.local/lib/python3.12/site-packages/sqlalchemy/util/compat.py", line 211, in raise_
    raise exception
  File "/home/airflow/.local/lib/python3.12/site-packages/sqlalchemy/engine/base.py", line 1890, in _execute_context
    self.dialect.do_executemany(
  File "/home/airflow/.local/lib/python3.12/site-packages/sqlalchemy/dialects/postgresql/psycopg2.py", line 1000, in do_executemany
    cursor.executemany(statement, parameters)
  File "/usr/local/lib/python3.12/encodings/utf_8.py", line 15, in decode
    def decode(input, errors='strict'):
    
  File "/home/airflow/.local/lib/python3.12/site-packages/airflow/models/taskinstance.py", line 3094, in signal_handler
    raise AirflowTaskTerminated("Task received SIGTERM signal")
airflow.exceptions.AirflowTaskTerminated: Task received SIGTERM signal

During handling of the above exception, another exception occurred:

Traceback (most recent call last):
  File "/home/airflow/.local/lib/python3.12/site-packages/sqlalchemy/engine/base.py", line 1910, in _execute_context
    self.dialect.do_execute(
  File "/home/airflow/.local/lib/python3.12/site-packages/sqlalchemy/engine/default.py", line 736, in do_execute
    cursor.execute(statement, parameters)
psycopg2.errors.ForeignKeyViolation: insert or update on table "task_fail" violates foreign key constraint "task_fail_ti_fkey"
DETAIL:  Key (dag_id, task_id, run_id, map_index)=(NY_Pipeline_ETL_and_ML_Training, step_create_original_table, scheduled__2024-12-23T00:00:00+00:00, -1) is not present in table "task_instance".


The above exception was the direct cause of the following exception:

Traceback (most recent call last):
  File "/home/airflow/.local/lib/python3.12/site-packages/airflow/task/task_runner/standard_task_runner.py", line 117, in _start_by_fork
    ret = args.func(args, dag=self.dag)
          ^^^^^^^^^^^^^^^^^^^^^^^^^^^^^
  File "/home/airflow/.local/lib/python3.12/site-packages/airflow/cli/cli_config.py", line 49, in command
    return func(*args, **kwargs)
           ^^^^^^^^^^^^^^^^^^^^^
  File "/home/airflow/.local/lib/python3.12/site-packages/airflow/utils/cli.py", line 115, in wrapper
    return f(*args, **kwargs)
           ^^^^^^^^^^^^^^^^^^
  File "/home/airflow/.local/lib/python3.12/site-packages/airflow/cli/commands/task_command.py", line 483, in task_run
    task_return_code = _run_task_by_selected_method(args, _dag, ti)
                       ^^^^^^^^^^^^^^^^^^^^^^^^^^^^^^^^^^^^^^^^^^^^
  File "/home/airflow/.local/lib/python3.12/site-packages/airflow/cli/commands/task_command.py", line 256, in _run_task_by_selected_method
    return _run_raw_task(args, ti)
           ^^^^^^^^^^^^^^^^^^^^^^^
  File "/home/airflow/.local/lib/python3.12/site-packages/airflow/cli/commands/task_command.py", line 341, in _run_raw_task
    return ti._run_raw_task(
           ^^^^^^^^^^^^^^^^^
  File "/home/airflow/.local/lib/python3.12/site-packages/airflow/utils/session.py", line 97, in wrapper
    return func(*args, session=session, **kwargs)
           ^^^^^^^^^^^^^^^^^^^^^^^^^^^^^^^^^^^^^^
  File "/home/airflow/.local/lib/python3.12/site-packages/airflow/models/taskinstance.py", line 3004, in _run_raw_task
    return _run_raw_task(
           ^^^^^^^^^^^^^^
  File "/home/airflow/.local/lib/python3.12/site-packages/airflow/models/taskinstance.py", line 327, in _run_raw_task
    ti.handle_failure(e, test_mode, context, session=session)
  File "/home/airflow/.local/lib/python3.12/site-packages/airflow/utils/session.py", line 94, in wrapper
    return func(*args, **kwargs)
           ^^^^^^^^^^^^^^^^^^^^^
  File "/home/airflow/.local/lib/python3.12/site-packages/airflow/models/taskinstance.py", line 3427, in handle_failure
    _handle_failure(
  File "/home/airflow/.local/lib/python3.12/site-packages/airflow/utils/session.py", line 94, in wrapper
    return func(*args, **kwargs)
           ^^^^^^^^^^^^^^^^^^^^^
  File "/home/airflow/.local/lib/python3.12/site-packages/airflow/api_internal/internal_api_call.py", line 139, in wrapper
    return func(*args, **kwargs)
           ^^^^^^^^^^^^^^^^^^^^^
  File "/home/airflow/.local/lib/python3.12/site-packages/airflow/models/taskinstance.py", line 1243, in _handle_failure
    TaskInstance.save_to_db(failure_context["ti"], session)
  File "/home/airflow/.local/lib/python3.12/site-packages/airflow/api_internal/internal_api_call.py", line 139, in wrapper
    return func(*args, **kwargs)
           ^^^^^^^^^^^^^^^^^^^^^
  File "/home/airflow/.local/lib/python3.12/site-packages/airflow/utils/session.py", line 94, in wrapper
    return func(*args, **kwargs)
           ^^^^^^^^^^^^^^^^^^^^^
  File "/home/airflow/.local/lib/python3.12/site-packages/airflow/models/taskinstance.py", line 3399, in save_to_db
    session.flush()
  File "/home/airflow/.local/lib/python3.12/site-packages/sqlalchemy/orm/session.py", line 3449, in flush
    self._flush(objects)
  File "/home/airflow/.local/lib/python3.12/site-packages/sqlalchemy/orm/session.py", line 3588, in _flush
    with util.safe_reraise():
         ^^^^^^^^^^^^^^^^^^^
  File "/home/airflow/.local/lib/python3.12/site-packages/sqlalchemy/util/langhelpers.py", line 70, in __exit__
    compat.raise_(
  File "/home/airflow/.local/lib/python3.12/site-packages/sqlalchemy/util/compat.py", line 211, in raise_
    raise exception
  File "/home/airflow/.local/lib/python3.12/site-packages/sqlalchemy/orm/session.py", line 3549, in _flush
    flush_context.execute()
  File "/home/airflow/.local/lib/python3.12/site-packages/sqlalchemy/orm/unitofwork.py", line 456, in execute
    rec.execute(self)
  File "/home/airflow/.local/lib/python3.12/site-packages/sqlalchemy/orm/unitofwork.py", line 630, in execute
    util.preloaded.orm_persistence.save_obj(
  File "/home/airflow/.local/lib/python3.12/site-packages/sqlalchemy/orm/persistence.py", line 245, in save_obj
    _emit_insert_statements(
  File "/home/airflow/.local/lib/python3.12/site-packages/sqlalchemy/orm/persistence.py", line 1238, in _emit_insert_statements
    result = connection._execute_20(
             ^^^^^^^^^^^^^^^^^^^^^^^
  File "/home/airflow/.local/lib/python3.12/site-packages/sqlalchemy/engine/base.py", line 1710, in _execute_20
    return meth(self, args_10style, kwargs_10style, execution_options)
           ^^^^^^^^^^^^^^^^^^^^^^^^^^^^^^^^^^^^^^^^^^^^^^^^^^^^^^^^^^^
  File "/home/airflow/.local/lib/python3.12/site-packages/sqlalchemy/sql/elements.py", line 334, in _execute_on_connection
    return connection._execute_clauseelement(
           ^^^^^^^^^^^^^^^^^^^^^^^^^^^^^^^^^^
  File "/home/airflow/.local/lib/python3.12/site-packages/sqlalchemy/engine/base.py", line 1577, in _execute_clauseelement
    ret = self._execute_context(
          ^^^^^^^^^^^^^^^^^^^^^^
  File "/home/airflow/.local/lib/python3.12/site-packages/sqlalchemy/engine/base.py", line 1953, in _execute_context
    self._handle_dbapi_exception(
  File "/home/airflow/.local/lib/python3.12/site-packages/sqlalchemy/engine/base.py", line 2134, in _handle_dbapi_exception
    util.raise_(
  File "/home/airflow/.local/lib/python3.12/site-packages/sqlalchemy/util/compat.py", line 211, in raise_
    raise exception
  File "/home/airflow/.local/lib/python3.12/site-packages/sqlalchemy/engine/base.py", line 1910, in _execute_context
    self.dialect.do_execute(
  File "/home/airflow/.local/lib/python3.12/site-packages/sqlalchemy/engine/default.py", line 736, in do_execute
    cursor.execute(statement, parameters)
sqlalchemy.exc.IntegrityError: (psycopg2.errors.ForeignKeyViolation) insert or update on table "task_fail" violates foreign key constraint "task_fail_ti_fkey"
DETAIL:  Key (dag_id, task_id, run_id, map_index)=(NY_Pipeline_ETL_and_ML_Training, step_create_original_table, scheduled__2024-12-23T00:00:00+00:00, -1) is not present in table "task_instance".

[SQL: INSERT INTO task_fail (task_id, dag_id, run_id, map_index, start_date, end_date, duration) VALUES (%(task_id)s, %(dag_id)s, %(run_id)s, %(map_index)s, %(start_date)s, %(end_date)s, %(duration)s) RETURNING task_fail.id]
[parameters: {'task_id': 'step_create_original_table', 'dag_id': 'NY_Pipeline_ETL_and_ML_Training', 'run_id': 'scheduled__2024-12-23T00:00:00+00:00', 'map_index': -1, 'start_date': datetime.datetime(2024, 12, 24, 0, 52, 48, 751862, tzinfo=Timezone('UTC')), 'end_date': datetime.datetime(2024, 12, 24, 0, 55, 5, 468504, tzinfo=Timezone('UTC')), 'duration': 136}]
(Background on this error at: https://sqlalche.me/e/14/gkpj)
[2024-12-24T00:55:05.563+0000] {process_utils.py:80} INFO - Process psutil.Process(pid=193, status='terminated', exitcode=1, started='00:52:48') (193) terminated with exit code 1
[2024-12-24T00:55:29.170+0000] {local_task_job_runner.py:123} INFO - ::group::Pre task execution logs
[2024-12-24T00:55:29.204+0000] {taskinstance.py:2612} INFO - Dependencies all met for dep_context=non-requeueable deps ti=<TaskInstance: NY_Pipeline_ETL_and_ML_Training.step_create_original_table scheduled__2024-12-23T00:00:00+00:00 [queued]>
[2024-12-24T00:55:29.238+0000] {taskinstance.py:2612} INFO - Dependencies all met for dep_context=requeueable deps ti=<TaskInstance: NY_Pipeline_ETL_and_ML_Training.step_create_original_table scheduled__2024-12-23T00:00:00+00:00 [queued]>
[2024-12-24T00:55:29.239+0000] {taskinstance.py:2865} INFO - Starting attempt 1 of 2
[2024-12-24T00:55:29.276+0000] {taskinstance.py:2888} INFO - Executing <Task(PythonOperator): step_create_original_table> on 2024-12-23 00:00:00+00:00
[2024-12-24T00:55:29.293+0000] {standard_task_runner.py:104} INFO - Running: ['***', 'tasks', 'run', 'NY_Pipeline_ETL_and_ML_Training', 'step_create_original_table', 'scheduled__2024-12-23T00:00:00+00:00', '--job-id', '6', '--raw', '--subdir', 'DAGS_FOLDER/etl_train_pipeline.py', '--cfg-path', '/tmp/tmphbz8og7u']
[2024-12-24T00:55:29.297+0000] {standard_task_runner.py:105} INFO - Job 6: Subtask step_create_original_table
[2024-12-24T00:55:29.298+0000] {logging_mixin.py:190} WARNING - /home/***/.local/lib/python3.12/site-packages/***/task/task_runner/standard_task_runner.py:70 DeprecationWarning: This process (pid=231) is multi-threaded, use of fork() may lead to deadlocks in the child.
[2024-12-24T00:55:29.299+0000] {standard_task_runner.py:72} INFO - Started process 233 to run task
[2024-12-24T00:55:29.398+0000] {task_command.py:467} INFO - Running <TaskInstance: NY_Pipeline_ETL_and_ML_Training.step_create_original_table scheduled__2024-12-23T00:00:00+00:00 [running]> on host 9c7b8f26d27a
[2024-12-24T00:55:29.553+0000] {taskinstance.py:3131} INFO - Exporting env vars: AIRFLOW_CTX_DAG_OWNER='Artur Tiburski' AIRFLOW_CTX_DAG_ID='NY_Pipeline_ETL_and_ML_Training' AIRFLOW_CTX_TASK_ID='step_create_original_table' AIRFLOW_CTX_EXECUTION_DATE='2024-12-23T00:00:00+00:00' AIRFLOW_CTX_TRY_NUMBER='1' AIRFLOW_CTX_DAG_RUN_ID='scheduled__2024-12-23T00:00:00+00:00'
[2024-12-24T00:55:29.555+0000] {taskinstance.py:731} INFO - ::endgroup::
[2024-12-24T01:01:47.718+0000] {local_task_job_runner.py:346} WARNING - State of this instance has been externally set to None. Terminating instance.
[2024-12-24T01:01:47.721+0000] {local_task_job_runner.py:245} INFO - ::endgroup::
[2024-12-24T01:01:47.724+0000] {process_utils.py:132} INFO - Sending 15 to group 233. PIDs of all processes in the group: [233]
[2024-12-24T01:01:47.731+0000] {process_utils.py:87} INFO - Sending the signal 15 to group 233
[2024-12-24T01:02:47.745+0000] {process_utils.py:150} WARNING - process psutil.Process(pid=233, name='airflow task ru', status='sleeping', started='00:55:28') did not respond to SIGTERM. Trying SIGKILL
[2024-12-24T01:02:47.748+0000] {process_utils.py:87} INFO - Sending the signal 9 to group 233
[2024-12-24T01:02:47.775+0000] {process_utils.py:80} INFO - Process psutil.Process(pid=233, name='airflow task ru', status='terminated', exitcode=<Negsignal.SIGKILL: -9>, started='00:55:28') (233) terminated with exit code -9
[2024-12-24T01:02:47.777+0000] {standard_task_runner.py:190} ERROR - ('Job 6 was killed before it finished (likely due to running out of memory)', 'For more information, see https://***.apache.org/docs/apache-***/stable/troubleshooting.html#LocalTaskJob-killed')
[2024-12-24T11:41:20.054+0000] {local_task_job_runner.py:123} INFO - ::group::Pre task execution logs
[2024-12-24T11:41:20.148+0000] {taskinstance.py:2612} INFO - Dependencies all met for dep_context=non-requeueable deps ti=<TaskInstance: NY_Pipeline_ETL_and_ML_Training.step_create_original_table scheduled__2024-12-23T00:00:00+00:00 [queued]>
[2024-12-24T11:41:20.175+0000] {taskinstance.py:2612} INFO - Dependencies all met for dep_context=requeueable deps ti=<TaskInstance: NY_Pipeline_ETL_and_ML_Training.step_create_original_table scheduled__2024-12-23T00:00:00+00:00 [queued]>
[2024-12-24T11:41:20.177+0000] {taskinstance.py:2865} INFO - Starting attempt 1 of 2
[2024-12-24T11:41:20.217+0000] {taskinstance.py:2888} INFO - Executing <Task(PythonOperator): step_create_original_table> on 2024-12-23 00:00:00+00:00
[2024-12-24T11:41:20.271+0000] {logging_mixin.py:190} WARNING - /home/***/.local/lib/python3.12/site-packages/***/task/task_runner/standard_task_runner.py:70 DeprecationWarning: This process (pid=232) is multi-threaded, use of fork() may lead to deadlocks in the child.
[2024-12-24T11:41:20.267+0000] {standard_task_runner.py:104} INFO - Running: ['***', 'tasks', 'run', 'NY_Pipeline_ETL_and_ML_Training', 'step_create_original_table', 'scheduled__2024-12-23T00:00:00+00:00', '--job-id', '3', '--raw', '--subdir', 'DAGS_FOLDER/etl_train_pipeline.py', '--cfg-path', '/tmp/tmpzx8jajff']
[2024-12-24T11:41:20.278+0000] {standard_task_runner.py:72} INFO - Started process 234 to run task
[2024-12-24T11:41:20.280+0000] {standard_task_runner.py:105} INFO - Job 3: Subtask step_create_original_table
[2024-12-24T11:41:20.468+0000] {task_command.py:467} INFO - Running <TaskInstance: NY_Pipeline_ETL_and_ML_Training.step_create_original_table scheduled__2024-12-23T00:00:00+00:00 [running]> on host 1d8802664e40
[2024-12-24T11:41:20.761+0000] {taskinstance.py:3131} INFO - Exporting env vars: AIRFLOW_CTX_DAG_OWNER='Artur Tiburski' AIRFLOW_CTX_DAG_ID='NY_Pipeline_ETL_and_ML_Training' AIRFLOW_CTX_TASK_ID='step_create_original_table' AIRFLOW_CTX_EXECUTION_DATE='2024-12-23T00:00:00+00:00' AIRFLOW_CTX_TRY_NUMBER='1' AIRFLOW_CTX_DAG_RUN_ID='scheduled__2024-12-23T00:00:00+00:00'
[2024-12-24T11:41:20.764+0000] {taskinstance.py:731} INFO - ::endgroup::
[2024-12-24T11:44:13.075+0000] {logging_mixin.py:190} INFO - Inserted records 0 to 1000
[2024-12-24T11:47:03.039+0000] {logging_mixin.py:190} INFO - Inserted records 1000 to 2000
[2024-12-24T11:49:53.163+0000] {logging_mixin.py:190} INFO - Inserted records 2000 to 3000
[2024-12-24T11:52:40.596+0000] {logging_mixin.py:190} INFO - Inserted records 3000 to 4000
[2024-12-24T11:54:54.973+0000] {logging_mixin.py:190} INFO - Inserted records 4000 to 4801
[2024-12-24T11:54:55.146+0000] {logging_mixin.py:190} INFO - Successfully loaded all 4801 records into ny_datasets.original_data
[2024-12-24T11:54:55.161+0000] {logging_mixin.py:190} INFO - Database connection closed.
[2024-12-24T11:54:55.173+0000] {python.py:240} INFO - Done. Returned value was: None
[2024-12-24T11:54:55.239+0000] {taskinstance.py:340} INFO - ::group::Post task execution logs
[2024-12-24T11:54:55.241+0000] {taskinstance.py:352} INFO - Marking task as SUCCESS. dag_id=NY_Pipeline_ETL_and_ML_Training, task_id=step_create_original_table, run_id=scheduled__2024-12-23T00:00:00+00:00, execution_date=20241223T000000, start_date=20241224T114120, end_date=20241224T115455
[2024-12-24T11:54:55.340+0000] {standard_task_runner.py:217} INFO - Process not found (most likely exited), stop collecting metrics
[2024-12-24T11:54:55.336+0000] {local_task_job_runner.py:266} INFO - Task exited with return code 0
[2024-12-24T11:54:55.386+0000] {taskinstance.py:3900} INFO - 0 downstream tasks scheduled from follow-on schedule check
[2024-12-24T11:54:55.389+0000] {local_task_job_runner.py:245} INFO - ::endgroup::
